<?xml version="1.0"?>
<robot name="roid1">

<!-- material color setting -->
<material name="#ffffff">
  <color rgba="1.000 1.000 1.000 1.0"/>
</material>
<material name="#ededed">
  <color rgba="0.933 0.933 0.933 1.0"/>
</material>
<material name="#00007e">
  <color rgba="0.000 0.000 0.498 1.0"/>
</material>
<material name="#ffaa00">
  <color rgba="1.000 0.667 0.000 1.0"/>
</material>
<material name="#0054ff">
  <color rgba="0.000 0.333 1.000 1.0"/>
</material>
<material name="#333333">
  <color rgba="0.200 0.200 0.200 1.0"/>
</material>
<material name="#ff0000">
  <color rgba="1.000 0.000 0.000 1.0"/>
</material>

  <link name="base_link">
    <inertial>
      <origin xyz="0 0 0" rpy="0 0 0"/>
      <mass value="0.0"/>
      <inertia ixx="0.01" ixy="0.0" ixz="0.0" iyy="0.0" iyz="0.0" izz="0.0"/>
    </inertial>
  </link>

  <joint name="base_link_to_c_waist_g" type="revolute">
    <origin xyz="0 0 0" rpy="0.0 0.0 0.0"/>
    <axis xyz="1 0 0"/>
    <parent link="base_link"/>
    <child link="c_waist_g"/>
    <limit lower="-3.14159" upper="3.14159" effort="0" velocity="0"/>
  </joint>

  <link name="c_waist_g">
    <inertial>
      <origin xyz="0 0 0" rpy="0 0 0"/>
      <mass value="0.142800"/>
      <inertia ixx="0.000268" ixy="-0.000000" ixz="0.000005" iyy="0.000292" iyz="0.000003" izz="0.000366"/>
    </inertial>
    <visual>
      <origin xyz="0 0 0" rpy="0 0 0"/>
      <geometry>
        <mesh filename="package://../meshes/c_waist_g.stl"/>
      </geometry>
      <material name="#ffffff"/>
    </visual>
    <collision>
      <origin xyz="0 0 0" rpy="0 0 0"/>
      <geometry>
        <mesh filename="package://../meshes/c_waist_g.stl"/>
      </geometry>
    </collision>
  </link>

  <joint name="c_waist_g_to_c_chest_g" type="revolute">
    <origin xyz="-0.0 0.0 0.046" rpy="0.0 0.0 0.0"/>
    <axis xyz="0 0 1"/>
    <parent link="c_waist_g"/>
    <child link="c_chest_g"/>
    <limit lower="-3.14159" upper="3.14159" effort="0" velocity="0"/>
  </joint>

  <link name="c_chest_g">
    <inertial>
      <origin xyz="0 0 0" rpy="0 0 0"/>
      <mass value="0.421500"/>
      <inertia ixx="0.003186" ixy="0.000009" ixz="-0.000261" iyy="0.003556" iyz="-0.000143" izz="0.004575"/>
    </inertial>
    <visual>
      <origin xyz="0 0 0" rpy="0 0 0"/>
      <geometry>
        <mesh filename="package://../meshes/c_chest_g.stl"/>
      </geometry>
      <material name="#0054ff"/>
    </visual>
    <collision>
      <origin xyz="0 0 0" rpy="0 0 0"/>
      <geometry>
        <mesh filename="package://../meshes/c_chest_g.stl"/>
      </geometry>
    </collision>
  </link>

  <joint name="c_chest_g_to_c_head_g" type="revolute">
    <origin xyz="0.0 0.0 0.126" rpy="0.0 0.0 0.0"/>
    <axis xyz="0 0 1"/>
    <parent link="c_chest_g"/>
    <child link="c_head_g"/>
    <limit lower="-3.14159" upper="3.14159" effort="0" velocity="0"/>
  </joint>

  <link name="c_head_g">
    <inertial>
      <origin xyz="0 0 0" rpy="0 0 0"/>
      <mass value="0.000113"/>
      <inertia ixx="0.000062" ixy="0.000000" ixz="0.000000" iyy="0.000048" iyz="0.000002" izz="0.000049"/>
    </inertial>
    <visual>
      <origin xyz="0 0 0" rpy="0 0 0"/>
      <geometry>
        <mesh filename="package://../meshes/c_head_g.stl"/>
      </geometry>
      <material name="#ffffff"/>
    </visual>
    <collision>
      <origin xyz="0 0 0" rpy="0 0 0"/>
      <geometry>
        <mesh filename="package://../meshes/c_head_g.stl"/>
      </geometry>
    </collision>
  </link>

  <joint name="c_chest_g_to_l_shoulder_g" type="revolute">
    <origin xyz="0.0 0.055 0.095" rpy="0.0 0.0 0.0"/>
    <axis xyz="0 1 0"/>
    <parent link="c_chest_g"/>
    <child link="l_shoulder_g"/>
    <limit lower="-3.14159" upper="3.14159" effort="0" velocity="0"/>
  </joint>

  <link name="l_shoulder_g">
    <inertial>
      <origin xyz="0 0 0" rpy="0 0 0"/>
      <mass value="0.014000"/>
      <inertia ixx="0.000016" ixy="-0.000001" ixz="0.000000" iyy="0.000022" iyz="-0.000000" izz="0.000026"/>
    </inertial>
    <visual>
      <origin xyz="0 0 0" rpy="0 0 0"/>
      <geometry>
        <mesh filename="package://../meshes/l_shoulder_g.stl"/>
      </geometry>
      <material name="#ffffff"/>
    </visual>
    <collision>
      <origin xyz="0 0 0" rpy="0 0 0"/>
      <geometry>
        <mesh filename="package://../meshes/l_shoulder_g.stl"/>
      </geometry>
    </collision>
  </link>

  <joint name="l_shoulder_g_to_l_arm_upper_g_a" type="revolute">
    <origin xyz="0.0 0.044 0.0" rpy="0.0 0.0 0.0"/>
    <axis xyz="0 0 1"/>
    <parent link="l_shoulder_g"/>
    <child link="l_arm_upper_g_a"/>
    <limit lower="-3.14159" upper="3.14159" effort="0" velocity="0"/>
  </joint>

  <link name="l_arm_upper_g_a">
    <inertial>
      <origin xyz="0 0 0" rpy="0 0 0"/>
      <mass value="0.098000"/>
      <inertia ixx="0.000243" ixy="-0.000001" ixz="-0.000049" iyy="0.000322" iyz="0.000000" izz="0.000131"/>
    </inertial>
    <visual>
      <origin xyz="0 0 0" rpy="0 0 0"/>
      <geometry>
        <mesh filename="package://../meshes/l_arm_upper_g_a.stl"/>
      </geometry>
      <material name="#ffffff"/>
    </visual>
    <collision>
      <origin xyz="0 0 0" rpy="0 0 0"/>
      <geometry>
        <mesh filename="package://../meshes/l_arm_upper_g_a.stl"/>
      </geometry>
    </collision>
  </link>

  <joint name="l_arm_upper_g_a_to_l_elbow_g" type="revolute">
    <origin xyz="0.009886 0.000365 -0.095384" rpy="0.0 0.0 0.0"/>
    <axis xyz="0 1 0"/>
    <parent link="l_arm_upper_g_a"/>
    <child link="l_elbow_g"/>
    <limit lower="-3.14159" upper="3.14159" effort="0" velocity="0"/>
  </joint>

  <link name="l_elbow_g">
    <inertial>
      <origin xyz="0 0 0" rpy="0 0 0"/>
      <mass value="0.044000"/>
      <inertia ixx="0.000034" ixy="0.000002" ixz="-0.000002" iyy="0.000051" iyz="-0.000001" izz="0.000062"/>
    </inertial>
    <visual>
      <origin xyz="0 0 0" rpy="0 0 0"/>
      <geometry>
        <mesh filename="package://../meshes/l_elbow_g.stl"/>
      </geometry>
      <material name="#ffffff"/>
    </visual>
    <collision>
      <origin xyz="0 0 0" rpy="0 0 0"/>
      <geometry>
        <mesh filename="package://../meshes/l_elbow_g.stl"/>
      </geometry>
    </collision>
  </link>

  <joint name="l_elbow_g_to_l_arm_lower_g_a" type="revolute">
    <origin xyz="0.0 0.0 -0.0365" rpy="0.0 0.0 0.0"/>
    <axis xyz="0 1 0"/>
    <parent link="l_elbow_g"/>
    <child link="l_arm_lower_g_a"/>
    <limit lower="-3.14159" upper="3.14159" effort="0" velocity="0"/>
  </joint>

  <link name="l_arm_lower_g_a">
    <inertial>
      <origin xyz="0 0 0" rpy="0 0 0"/>
      <mass value="0.030000"/>
      <inertia ixx="0.000105" ixy="0.000001" ixz="0.000003" iyy="0.000095" iyz="0.000002" izz="0.000030"/>
    </inertial>
    <visual>
      <origin xyz="0 0 0" rpy="0 0 0"/>
      <geometry>
        <mesh filename="package://../meshes/l_arm_lower_g_a.stl"/>
      </geometry>
      <material name="#ffffff"/>
    </visual>
    <collision>
      <origin xyz="0 0 0" rpy="0 0 0"/>
      <geometry>
        <mesh filename="package://../meshes/l_arm_lower_g_a.stl"/>
      </geometry>
    </collision>
  </link>

  <joint name="l_arm_lower_g_a_to_l_arm_lower_g_b" type="revolute">
    <origin xyz="0.0 0.0 -0.033" rpy="0.0 0.0 0.0"/>
    <axis xyz="0 0 1"/>
    <parent link="l_arm_lower_g_a"/>
    <child link="l_arm_lower_g_b"/>
    <limit lower="-3.14159" upper="3.14159" effort="0" velocity="0"/>
  </joint>

  <link name="l_arm_lower_g_b">
    <inertial>
      <origin xyz="0 0 0" rpy="0 0 0"/>
      <mass value="0.000000"/>
      <inertia ixx="0.000000" ixy="0.000000" ixz="0.000000" iyy="0.000000" iyz="0.000000" izz="0.000000"/>
    </inertial>
    <visual>
      <origin xyz="0 0 0" rpy="0 0 0"/>
      <geometry>
        <mesh filename="package://../meshes/l_arm_lower_g_b.stl"/>
      </geometry>
      <material name="#ffffff"/>
    </visual>
    <collision>
      <origin xyz="0 0 0" rpy="0 0 0"/>
      <geometry>
        <mesh filename="package://../meshes/l_arm_lower_g_b.stl"/>
      </geometry>
    </collision>
  </link>

  <joint name="l_arm_lower_g_b_to_l_hand_g_a" type="fixed">
    <origin xyz="0.0 0.01 -0.075" rpy="0.0 0.0 0.0"/>
    <parent link="l_arm_lower_g_b"/>
    <child link="l_hand_g_a"/>
  </joint>

  <link name="l_hand_g_a">
    <inertial>
      <origin xyz="0 0 0" rpy="0 0 0"/>
      <mass value="0.000000"/>
      <inertia ixx="0.000000" ixy="0.000000" ixz="0.000000" iyy="0.000000" iyz="0.000000" izz="0.000000"/>
    </inertial>
    <visual>
      <origin xyz="0 0 0" rpy="0 0 0"/>
      <geometry>
        <mesh filename="package://../meshes/l_hand_g_a.stl"/>
      </geometry>
      <material name="#333333"/>
    </visual>
    <collision>
      <origin xyz="0 0 0" rpy="0 0 0"/>
      <geometry>
        <mesh filename="package://../meshes/l_hand_g_a.stl"/>
      </geometry>
    </collision>
  </link>

  <joint name="l_hand_g_a_to_l_fingers_g_a" type="revolute">
    <origin xyz="0.000144 1e-06 -0.047" rpy="0.0 0.0 0.0"/>
    <axis xyz="1 0 0"/>
    <parent link="l_hand_g_a"/>
    <child link="l_fingers_g_a"/>
    <limit lower="-3.14159" upper="3.14159" effort="0" velocity="0"/>
  </joint>

  <link name="l_fingers_g_a">
    <inertial>
      <origin xyz="0 0 0" rpy="0 0 0"/>
      <mass value="0.000000"/>
      <inertia ixx="0.000000" ixy="0.000000" ixz="0.000000" iyy="0.000000" iyz="0.000000" izz="0.000000"/>
    </inertial>
    <visual>
      <origin xyz="0 0 0" rpy="0 0 0"/>
      <geometry>
        <mesh filename="package://../meshes/l_fingers_g_a.stl"/>
      </geometry>
      <material name="#333333"/>
    </visual>
    <collision>
      <origin xyz="0 0 0" rpy="0 0 0"/>
      <geometry>
        <mesh filename="package://../meshes/l_fingers_g_a.stl"/>
      </geometry>
    </collision>
  </link>

  <joint name="l_arm_upper_g_a_to_l_arm_upper_dec" type="fixed">
    <origin xyz="0.0 0.0 0.0" rpy="0.0 0.0 0.0"/>
    <parent link="l_arm_upper_g_a"/>
    <child link="l_arm_upper_dec"/>
  </joint>

  <link name="l_arm_upper_dec">
    <inertial>
      <origin xyz="0 0 0" rpy="0 0 0"/>
      <mass value="0.000003"/>
      <inertia ixx="0.000000" ixy="0.000000" ixz="0.000000" iyy="0.000000" iyz="0.000000" izz="0.000000"/>
    </inertial>
    <visual>
      <origin xyz="0 0 0" rpy="0 0 0"/>
      <geometry>
        <mesh filename="package://../meshes/l_arm_upper_dec.stl"/>
      </geometry>
      <material name="#ededed"/>
    </visual>
    <collision>
      <origin xyz="0 0 0" rpy="0 0 0"/>
      <geometry>
        <mesh filename="package://../meshes/l_arm_upper_dec.stl"/>
      </geometry>
    </collision>
  </link>

  <joint name="l_shoulder_g_to_l_shoulder_g_a" type="revolute">
    <origin xyz="0.0 0.02 0.0" rpy="0.0 0.0 0.0"/>
    <axis xyz="1 0 0"/>
    <parent link="l_shoulder_g"/>
    <child link="l_shoulder_g_a"/>
    <limit lower="-3.14159" upper="3.14159" effort="0" velocity="0"/>
  </joint>

  <link name="l_shoulder_g_a">
    <inertial>
      <origin xyz="0 0 0" rpy="0 0 0"/>
      <mass value="0.000000"/>
      <inertia ixx="0.000000" ixy="0.000000" ixz="0.000000" iyy="0.000000" iyz="0.000000" izz="0.000000"/>
    </inertial>
    <visual>
      <origin xyz="0 0 0" rpy="0 0 0"/>
      <geometry>
        <mesh filename="package://../meshes/l_shoulder_g_a.stl"/>
      </geometry>
      <material name="#ffffff"/>
    </visual>
    <collision>
      <origin xyz="0 0 0" rpy="0 0 0"/>
      <geometry>
        <mesh filename="package://../meshes/l_shoulder_g_a.stl"/>
      </geometry>
    </collision>
  </link>

  <joint name="c_chest_g_to_r_shoulder_g" type="revolute">
    <origin xyz="0.0 -0.055 0.095" rpy="0.0 0.0 0.0"/>
    <axis xyz="0 1 0"/>
    <parent link="c_chest_g"/>
    <child link="r_shoulder_g"/>
    <limit lower="-3.14159" upper="3.14159" effort="0" velocity="0"/>
  </joint>

  <link name="r_shoulder_g">
    <inertial>
      <origin xyz="0 0 0" rpy="0 0 0"/>
      <mass value="0.014000"/>
      <inertia ixx="0.000016" ixy="0.000001" ixz="0.000000" iyy="0.000010" iyz="0.000000" izz="0.000021"/>
    </inertial>
    <visual>
      <origin xyz="0 0 0" rpy="0 0 0"/>
      <geometry>
        <mesh filename="package://../meshes/r_shoulder_g.stl"/>
      </geometry>
      <material name="#ffffff"/>
    </visual>
    <collision>
      <origin xyz="0 0 0" rpy="0 0 0"/>
      <geometry>
        <mesh filename="package://../meshes/r_shoulder_g.stl"/>
      </geometry>
    </collision>
  </link>

  <joint name="r_shoulder_g_to_r_arm_upper_g_a" type="revolute">
    <origin xyz="0.0 -0.044 0.0" rpy="0.0 0.0 0.0"/>
    <axis xyz="0 0 1"/>
    <parent link="r_shoulder_g"/>
    <child link="r_arm_upper_g_a"/>
    <limit lower="-3.14159" upper="3.14159" effort="0" velocity="0"/>
  </joint>

  <link name="r_arm_upper_g_a">
    <inertial>
      <origin xyz="0 0 0" rpy="0 0 0"/>
      <mass value="0.098000"/>
      <inertia ixx="0.000074" ixy="0.000000" ixz="-0.000015" iyy="0.000098" iyz="-0.000000" izz="0.000040"/>
    </inertial>
    <visual>
      <origin xyz="0 0 0" rpy="0 0 0"/>
      <geometry>
        <mesh filename="package://../meshes/r_arm_upper_g_a.stl"/>
      </geometry>
      <material name="#ffffff"/>
    </visual>
    <collision>
      <origin xyz="0 0 0" rpy="0 0 0"/>
      <geometry>
        <mesh filename="package://../meshes/r_arm_upper_g_a.stl"/>
      </geometry>
    </collision>
  </link>

  <joint name="r_arm_upper_g_a_to_r_elbow_g" type="revolute">
    <origin xyz="0.009886 -0.000365 -0.095384" rpy="0.0 0.0 0.0"/>
    <axis xyz="0 1 0"/>
    <parent link="r_arm_upper_g_a"/>
    <child link="r_elbow_g"/>
    <limit lower="-3.14159" upper="3.14159" effort="0" velocity="0"/>
  </joint>

  <link name="r_elbow_g">
    <inertial>
      <origin xyz="0 0 0" rpy="0 0 0"/>
      <mass value="0.044000"/>
      <inertia ixx="0.000008" ixy="-0.000001" ixz="-0.000001" iyy="0.000013" iyz="0.000000" izz="0.000016"/>
    </inertial>
    <visual>
      <origin xyz="0 0 0" rpy="0 0 0"/>
      <geometry>
        <mesh filename="package://../meshes/r_elbow_g.stl"/>
      </geometry>
      <material name="#ffffff"/>
    </visual>
    <collision>
      <origin xyz="0 0 0" rpy="0 0 0"/>
      <geometry>
        <mesh filename="package://../meshes/r_elbow_g.stl"/>
      </geometry>
    </collision>
  </link>

  <joint name="r_elbow_g_to_r_arm_lower_g_a" type="revolute">
    <origin xyz="0.0 -0.0 -0.0365" rpy="0.0 0.0 0.0"/>
    <axis xyz="0 1 0"/>
    <parent link="r_elbow_g"/>
    <child link="r_arm_lower_g_a"/>
    <limit lower="-3.14159" upper="3.14159" effort="0" velocity="0"/>
  </joint>

  <link name="r_arm_lower_g_a">
    <inertial>
      <origin xyz="0 0 0" rpy="0 0 0"/>
      <mass value="0.030000"/>
      <inertia ixx="0.000023" ixy="-0.000000" ixz="0.000001" iyy="0.000021" iyz="-0.000000" izz="0.000007"/>
    </inertial>
    <visual>
      <origin xyz="0 0 0" rpy="0 0 0"/>
      <geometry>
        <mesh filename="package://../meshes/r_arm_lower_g_a.stl"/>
      </geometry>
      <material name="#ffffff"/>
    </visual>
    <collision>
      <origin xyz="0 0 0" rpy="0 0 0"/>
      <geometry>
        <mesh filename="package://../meshes/r_arm_lower_g_a.stl"/>
      </geometry>
    </collision>
  </link>

  <joint name="r_arm_lower_g_a_to_r_arm_lower_g_b" type="revolute">
    <origin xyz="0.0 -0.0 -0.033" rpy="0.0 0.0 0.0"/>
    <axis xyz="0 0 1"/>
    <parent link="r_arm_lower_g_a"/>
    <child link="r_arm_lower_g_b"/>
    <limit lower="-3.14159" upper="3.14159" effort="0" velocity="0"/>
  </joint>

  <link name="r_arm_lower_g_b">
    <inertial>
      <origin xyz="0 0 0" rpy="0 0 0"/>
      <mass value="0.000000"/>
      <inertia ixx="0.000000" ixy="0.000000" ixz="0.000000" iyy="0.000000" iyz="0.000000" izz="0.000000"/>
    </inertial>
    <visual>
      <origin xyz="0 0 0" rpy="0 0 0"/>
      <geometry>
        <mesh filename="package://../meshes/r_arm_lower_g_b.stl"/>
      </geometry>
      <material name="#ffffff"/>
    </visual>
    <collision>
      <origin xyz="0 0 0" rpy="0 0 0"/>
      <geometry>
        <mesh filename="package://../meshes/r_arm_lower_g_b.stl"/>
      </geometry>
    </collision>
  </link>

  <joint name="r_arm_lower_g_b_to_r_hand_g_a" type="fixed">
    <origin xyz="0.0 -0.01 -0.075" rpy="0.0 0.0 0.0"/>
    <parent link="r_arm_lower_g_b"/>
    <child link="r_hand_g_a"/>
  </joint>

  <link name="r_hand_g_a">
    <inertial>
      <origin xyz="0 0 0" rpy="0 0 0"/>
      <mass value="0.000000"/>
      <inertia ixx="0.000000" ixy="0.000000" ixz="0.000000" iyy="0.000000" iyz="0.000000" izz="0.000000"/>
    </inertial>
    <visual>
      <origin xyz="0 0 0" rpy="0 0 0"/>
      <geometry>
        <mesh filename="package://../meshes/r_hand_g_a.stl"/>
      </geometry>
      <material name="#333333"/>
    </visual>
    <collision>
      <origin xyz="0 0 0" rpy="0 0 0"/>
      <geometry>
        <mesh filename="package://../meshes/r_hand_g_a.stl"/>
      </geometry>
    </collision>
  </link>

  <joint name="r_hand_g_a_to_r_fingers_g_a" type="revolute">
    <origin xyz="0.000144 -1e-06 -0.047" rpy="0.0 0.0 0.0"/>
    <axis xyz="1 0 0"/>
    <parent link="r_hand_g_a"/>
    <child link="r_fingers_g_a"/>
    <limit lower="-3.14159" upper="3.14159" effort="0" velocity="0"/>
  </joint>

  <link name="r_fingers_g_a">
    <inertial>
      <origin xyz="0 0 0" rpy="0 0 0"/>
      <mass value="0.000000"/>
      <inertia ixx="0.000000" ixy="0.000000" ixz="0.000000" iyy="0.000000" iyz="0.000000" izz="0.000000"/>
    </inertial>
    <visual>
      <origin xyz="0 0 0" rpy="0 0 0"/>
      <geometry>
        <mesh filename="package://../meshes/r_fingers_g_a.stl"/>
      </geometry>
      <material name="#333333"/>
    </visual>
    <collision>
      <origin xyz="0 0 0" rpy="0 0 0"/>
      <geometry>
        <mesh filename="package://../meshes/r_fingers_g_a.stl"/>
      </geometry>
    </collision>
  </link>

  <joint name="r_arm_upper_g_a_to_r_arm_upper_dec" type="fixed">
    <origin xyz="0.0 -0.0 0.0" rpy="0.0 0.0 0.0"/>
    <parent link="r_arm_upper_g_a"/>
    <child link="r_arm_upper_dec"/>
  </joint>

  <link name="r_arm_upper_dec">
    <inertial>
      <origin xyz="0 0 0" rpy="0 0 0"/>
      <mass value="0.000003"/>
      <inertia ixx="0.000000" ixy="0.000000" ixz="0.000000" iyy="0.000000" iyz="0.000000" izz="0.000000"/>
    </inertial>
    <visual>
      <origin xyz="0 0 0" rpy="0 0 0"/>
      <geometry>
        <mesh filename="package://../meshes/r_arm_upper_dec.stl"/>
      </geometry>
      <material name="#ededed"/>
    </visual>
    <collision>
      <origin xyz="0 0 0" rpy="0 0 0"/>
      <geometry>
        <mesh filename="package://../meshes/r_arm_upper_dec.stl"/>
      </geometry>
    </collision>
  </link>

  <joint name="r_shoulder_g_to_r_shoulder_g_a" type="revolute">
    <origin xyz="0.0 -0.02 0.0" rpy="0.0 0.0 0.0"/>
    <axis xyz="1 0 0"/>
    <parent link="r_shoulder_g"/>
    <child link="r_shoulder_g_a"/>
    <limit lower="-3.14159" upper="3.14159" effort="0" velocity="0"/>
  </joint>

  <link name="r_shoulder_g_a">
    <inertial>
      <origin xyz="0 0 0" rpy="0 0 0"/>
      <mass value="0.000000"/>
      <inertia ixx="0.000000" ixy="0.000000" ixz="0.000000" iyy="0.000000" iyz="0.000000" izz="0.000000"/>
    </inertial>
    <visual>
      <origin xyz="0 0 0" rpy="0 0 0"/>
      <geometry>
        <mesh filename="package://../meshes/r_shoulder_g_a.stl"/>
      </geometry>
      <material name="#ffffff"/>
    </visual>
    <collision>
      <origin xyz="0 0 0" rpy="0 0 0"/>
      <geometry>
        <mesh filename="package://../meshes/r_shoulder_g_a.stl"/>
      </geometry>
    </collision>
  </link>

  <joint name="c_chest_g_to_c_chest_dec1" type="fixed">
    <origin xyz="-0.04 0.0 0.0" rpy="0.0 0.0 0.0"/>
    <parent link="c_chest_g"/>
    <child link="c_chest_dec1"/>
  </joint>

  <link name="c_chest_dec1">
    <inertial>
      <origin xyz="0 0 0" rpy="0 0 0"/>
      <mass value="0.086483"/>
      <inertia ixx="0.000640" ixy="0.000001" ixz="0.000080" iyy="0.000348" iyz="-0.000045" izz="0.000548"/>
    </inertial>
    <visual>
      <origin xyz="0 0 0" rpy="0 0 0"/>
      <geometry>
        <mesh filename="package://../meshes/c_chest_dec1.stl"/>
      </geometry>
      <material name="#ededed"/>
    </visual>
    <collision>
      <origin xyz="0 0 0" rpy="0 0 0"/>
      <geometry>
        <mesh filename="package://../meshes/c_chest_dec1.stl"/>
      </geometry>
    </collision>
  </link>

  <joint name="c_waist_g_to_l_hipjoint_upper_g" type="revolute">
    <origin xyz="0.0 0.035 -0.021" rpy="0.0 0.0 0.0"/>
    <axis xyz="0 0 1"/>
    <parent link="c_waist_g"/>
    <child link="l_hipjoint_upper_g"/>
    <limit lower="-3.14159" upper="3.14159" effort="0" velocity="0"/>
  </joint>

  <link name="l_hipjoint_upper_g">
    <inertial>
      <origin xyz="0 0 0" rpy="0 0 0"/>
      <mass value="0.011500"/>
      <inertia ixx="0.000014" ixy="-0.000000" ixz="-0.000000" iyy="0.000022" iyz="-0.000002" izz="0.000020"/>
    </inertial>
    <visual>
      <origin xyz="0 0 0" rpy="0 0 0"/>
      <geometry>
        <mesh filename="package://../meshes/l_hipjoint_upper_g.stl"/>
      </geometry>
      <material name="#ffffff"/>
    </visual>
    <collision>
      <origin xyz="0 0 0" rpy="0 0 0"/>
      <geometry>
        <mesh filename="package://../meshes/l_hipjoint_upper_g.stl"/>
      </geometry>
    </collision>
  </link>

  <joint name="l_hipjoint_upper_g_to_l_hipjoint_lower_g" type="revolute">
    <origin xyz="-0.01 -0.0 -0.031" rpy="0.0 0.0 0.0"/>
    <axis xyz="1 0 0"/>
    <parent link="l_hipjoint_upper_g"/>
    <child link="l_hipjoint_lower_g"/>
    <limit lower="-3.14159" upper="3.14159" effort="0" velocity="0"/>
  </joint>

  <link name="l_hipjoint_lower_g">
    <inertial>
      <origin xyz="0 0 0" rpy="0 0 0"/>
      <mass value="0.058000"/>
      <inertia ixx="0.000131" ixy="-0.000003" ixz="0.000001" iyy="0.000085" iyz="-0.000001" izz="0.000102"/>
    </inertial>
    <visual>
      <origin xyz="0 0 0" rpy="0 0 0"/>
      <geometry>
        <mesh filename="package://../meshes/l_hipjoint_lower_g.stl"/>
      </geometry>
      <material name="#ffffff"/>
    </visual>
    <collision>
      <origin xyz="0 0 0" rpy="0 0 0"/>
      <geometry>
        <mesh filename="package://../meshes/l_hipjoint_lower_g.stl"/>
      </geometry>
    </collision>
  </link>

  <joint name="l_hipjoint_lower_g_to_l_leg_upper_g" type="revolute">
    <origin xyz="0.0 0.0 -0.03" rpy="0.0 0.0 0.0"/>
    <axis xyz="0 1 0"/>
    <parent link="l_hipjoint_lower_g"/>
    <child link="l_leg_upper_g"/>
    <limit lower="-3.14159" upper="3.14159" effort="0" velocity="0"/>
  </joint>

  <link name="l_leg_upper_g">
    <inertial>
      <origin xyz="0 0 0" rpy="0 0 0"/>
      <mass value="0.091000"/>
      <inertia ixx="0.016863" ixy="0.000094" ixz="-0.001532" iyy="0.019971" iyz="-0.000019" izz="0.007465"/>
    </inertial>
    <visual>
      <origin xyz="0 0 0" rpy="0 0 0"/>
      <geometry>
        <mesh filename="package://../meshes/l_leg_upper_g.stl"/>
      </geometry>
      <material name="#ffffff"/>
    </visual>
    <collision>
      <origin xyz="0 0 0" rpy="0 0 0"/>
      <geometry>
        <mesh filename="package://../meshes/l_leg_upper_g.stl"/>
      </geometry>
    </collision>
  </link>

  <joint name="l_leg_upper_g_to_l_knee_g" type="revolute">
    <origin xyz="0.01 0.0 -0.12" rpy="0.0 0.0 0.0"/>
    <axis xyz="0 1 0"/>
    <parent link="l_leg_upper_g"/>
    <child link="l_knee_g"/>
    <limit lower="-3.14159" upper="3.14159" effort="0" velocity="0"/>
  </joint>

  <link name="l_knee_g">
    <inertial>
      <origin xyz="0 0 0" rpy="0 0 0"/>
      <mass value="0.000000"/>
      <inertia ixx="0.000000" ixy="0.000000" ixz="0.000000" iyy="0.000000" iyz="0.000000" izz="0.000000"/>
    </inertial>
    <visual>
      <origin xyz="0 0 0" rpy="0 0 0"/>
      <geometry>
        <mesh filename="package://../meshes/l_knee_g.stl"/>
      </geometry>
      <material name="#ffffff"/>
    </visual>
    <collision>
      <origin xyz="0 0 0" rpy="0 0 0"/>
      <geometry>
        <mesh filename="package://../meshes/l_knee_g.stl"/>
      </geometry>
    </collision>
  </link>

  <joint name="l_knee_g_to_l_leg_lower_g" type="revolute">
    <origin xyz="0.0 -0.0 -0.062" rpy="0.0 0.0 0.0"/>
    <axis xyz="0 1 0"/>
    <parent link="l_knee_g"/>
    <child link="l_leg_lower_g"/>
    <limit lower="-3.14159" upper="3.14159" effort="0" velocity="0"/>
  </joint>

  <link name="l_leg_lower_g">
    <inertial>
      <origin xyz="0 0 0" rpy="0 0 0"/>
      <mass value="0.061000"/>
      <inertia ixx="0.000147" ixy="-0.000000" ixz="-0.000004" iyy="0.000127" iyz="0.000006" izz="0.000063"/>
    </inertial>
    <visual>
      <origin xyz="0 0 0" rpy="0 0 0"/>
      <geometry>
        <mesh filename="package://../meshes/l_leg_lower_g.stl"/>
      </geometry>
      <material name="#ffffff"/>
    </visual>
    <collision>
      <origin xyz="0 0 0" rpy="0 0 0"/>
      <geometry>
        <mesh filename="package://../meshes/l_leg_lower_g.stl"/>
      </geometry>
    </collision>
  </link>

  <joint name="l_leg_lower_g_to_l_ankle_g" type="revolute">
    <origin xyz="-0.01 0.0 -0.12" rpy="0.0 0.0 0.0"/>
    <axis xyz="1 0 0"/>
    <parent link="l_leg_lower_g"/>
    <child link="l_ankle_g"/>
    <limit lower="-3.14159" upper="3.14159" effort="0" velocity="0"/>
  </joint>

  <link name="l_ankle_g">
    <inertial>
      <origin xyz="0 0 0" rpy="0 0 0"/>
      <mass value="0.058000"/>
      <inertia ixx="0.000132" ixy="-0.000003" ixz="-0.000001" iyy="0.000087" iyz="0.000001" izz="0.000103"/>
    </inertial>
    <visual>
      <origin xyz="0 0 0" rpy="0 0 0"/>
      <geometry>
        <mesh filename="package://../meshes/l_ankle_g.stl"/>
      </geometry>
      <material name="#ffffff"/>
    </visual>
    <collision>
      <origin xyz="0 0 0" rpy="0 0 0"/>
      <geometry>
        <mesh filename="package://../meshes/l_ankle_g.stl"/>
      </geometry>
    </collision>
  </link>

  <joint name="l_ankle_g_to_l_foot_g" type="revolute">
    <origin xyz="0.0 -0.0 -0.031" rpy="0.0 0.0 0.0"/>
    <axis xyz="1 0 0"/>
    <parent link="l_ankle_g"/>
    <child link="l_foot_g"/>
    <limit lower="-3.14159" upper="3.14159" effort="0" velocity="0"/>
  </joint>

  <link name="l_foot_g">
    <inertial>
      <origin xyz="0 0 0" rpy="0 0 0"/>
      <mass value="0.045000"/>
      <inertia ixx="0.009911" ixy="-0.000400" ixz="-0.000365" iyy="0.022896" iyz="0.000519" izz="0.030212"/>
    </inertial>
    <visual>
      <origin xyz="0 0 0" rpy="0 0 0"/>
      <geometry>
        <mesh filename="package://../meshes/l_foot_g.stl"/>
      </geometry>
      <material name="#ffffff"/>
    </visual>
    <collision>
      <origin xyz="0 0 0" rpy="0 0 0"/>
      <geometry>
        <mesh filename="package://../meshes/l_foot_g.stl"/>
      </geometry>
    </collision>
  </link>

  <joint name="l_foot_g_to_l_toe_g" type="revolute">
    <origin xyz="0.07 0.02 -0.03" rpy="0.0 0.0 0.0"/>
    <axis xyz="1 0 0"/>
    <parent link="l_foot_g"/>
    <child link="l_toe_g"/>
    <limit lower="-3.14159" upper="3.14159" effort="0" velocity="0"/>
  </joint>

  <link name="l_toe_g">
    <inertial>
      <origin xyz="0 0 0" rpy="0 0 0"/>
      <mass value="0.000000"/>
      <inertia ixx="0.000000" ixy="0.000000" ixz="0.000000" iyy="0.000000" iyz="0.000000" izz="0.000000"/>
    </inertial>
    <visual>
      <origin xyz="0 0 0" rpy="0 0 0"/>
      <geometry>
        <mesh filename="package://../meshes/l_toe_g.stl"/>
      </geometry>
      <material name="#ff0000"/>
    </visual>
    <collision>
      <origin xyz="0 0 0" rpy="0 0 0"/>
      <geometry>
        <mesh filename="package://../meshes/l_toe_g.stl"/>
      </geometry>
    </collision>
  </link>

  <joint name="l_leg_lower_g_to_l_leg_lower_g_c" type="revolute">
    <origin xyz="0.0 0.0 0.0" rpy="0.0 0.0 0.0"/>
    <axis xyz="1 0 0"/>
    <parent link="l_leg_lower_g"/>
    <child link="l_leg_lower_g_c"/>
    <limit lower="-3.14159" upper="3.14159" effort="0" velocity="0"/>
  </joint>

  <link name="l_leg_lower_g_c">
    <inertial>
      <origin xyz="0 0 0" rpy="0 0 0"/>
      <mass value="0.000014"/>
      <inertia ixx="0.000013" ixy="0.000000" ixz="0.000001" iyy="0.000012" iyz="0.000000" izz="0.000005"/>
    </inertial>
    <visual>
      <origin xyz="0 0 0" rpy="0 0 0"/>
      <geometry>
        <mesh filename="package://../meshes/l_leg_lower_g_c.stl"/>
      </geometry>
      <material name="#ffffff"/>
    </visual>
    <collision>
      <origin xyz="0 0 0" rpy="0 0 0"/>
      <geometry>
        <mesh filename="package://../meshes/l_leg_lower_g_c.stl"/>
      </geometry>
    </collision>
  </link>

  <joint name="l_leg_upper_g_to_l_leg_upper_g_c" type="revolute">
    <origin xyz="0.0 0.0 -0.12" rpy="0.0 0.0 0.0"/>
    <axis xyz="0 1 0"/>
    <parent link="l_leg_upper_g"/>
    <child link="l_leg_upper_g_c"/>
    <limit lower="-3.14159" upper="3.14159" effort="0" velocity="0"/>
  </joint>

  <link name="l_leg_upper_g_c">
    <inertial>
      <origin xyz="0 0 0" rpy="0 0 0"/>
      <mass value="0.000009"/>
      <inertia ixx="0.000000" ixy="-0.000000" ixz="-0.000000" iyy="0.000000" iyz="0.000000" izz="0.000000"/>
    </inertial>
    <visual>
      <origin xyz="0 0 0" rpy="0 0 0"/>
      <geometry>
        <mesh filename="package://../meshes/l_leg_upper_g_c.stl"/>
      </geometry>
      <material name="#ffffff"/>
    </visual>
    <collision>
      <origin xyz="0 0 0" rpy="0 0 0"/>
      <geometry>
        <mesh filename="package://../meshes/l_leg_upper_g_c.stl"/>
      </geometry>
    </collision>
  </link>

  <joint name="c_waist_g_to_r_hipjoint_upper_g" type="revolute">
    <origin xyz="0.0 -0.035 -0.021" rpy="0.0 0.0 0.0"/>
    <axis xyz="0 0 1"/>
    <parent link="c_waist_g"/>
    <child link="r_hipjoint_upper_g"/>
    <limit lower="-3.14159" upper="3.14159" effort="0" velocity="0"/>
  </joint>

  <link name="r_hipjoint_upper_g">
    <inertial>
      <origin xyz="0 0 0" rpy="0 0 0"/>
      <mass value="0.011500"/>
      <inertia ixx="0.000013" ixy="0.000000" ixz="0.000000" iyy="0.000019" iyz="0.000001" izz="0.000015"/>
    </inertial>
    <visual>
      <origin xyz="0 0 0" rpy="0 0 0"/>
      <geometry>
        <mesh filename="package://../meshes/r_hipjoint_upper_g.stl"/>
      </geometry>
      <material name="#ffffff"/>
    </visual>
    <collision>
      <origin xyz="0 0 0" rpy="0 0 0"/>
      <geometry>
        <mesh filename="package://../meshes/r_hipjoint_upper_g.stl"/>
      </geometry>
    </collision>
  </link>

  <joint name="r_hipjoint_upper_g_to_r_hipjoint_lower_g" type="revolute">
    <origin xyz="-0.01 0.0 -0.031" rpy="0.0 0.0 0.0"/>
    <axis xyz="1 0 0"/>
    <parent link="r_hipjoint_upper_g"/>
    <child link="r_hipjoint_lower_g"/>
    <limit lower="-3.14159" upper="3.14159" effort="0" velocity="0"/>
  </joint>

  <link name="r_hipjoint_lower_g">
    <inertial>
      <origin xyz="0 0 0" rpy="0 0 0"/>
      <mass value="0.058000"/>
      <inertia ixx="0.000040" ixy="0.000001" ixz="-0.000001" iyy="0.000026" iyz="-0.000000" izz="0.000031"/>
    </inertial>
    <visual>
      <origin xyz="0 0 0" rpy="0 0 0"/>
      <geometry>
        <mesh filename="package://../meshes/r_hipjoint_lower_g.stl"/>
      </geometry>
      <material name="#ffffff"/>
    </visual>
    <collision>
      <origin xyz="0 0 0" rpy="0 0 0"/>
      <geometry>
        <mesh filename="package://../meshes/r_hipjoint_lower_g.stl"/>
      </geometry>
    </collision>
  </link>

  <joint name="r_hipjoint_lower_g_to_r_leg_upper_g" type="revolute">
    <origin xyz="0.0 -0.0 -0.03" rpy="0.0 0.0 0.0"/>
    <axis xyz="0 1 0"/>
    <parent link="r_hipjoint_lower_g"/>
    <child link="r_leg_upper_g"/>
    <limit lower="-3.14159" upper="3.14159" effort="0" velocity="0"/>
  </joint>

  <link name="r_leg_upper_g">
    <inertial>
      <origin xyz="0 0 0" rpy="0 0 0"/>
      <mass value="0.091000"/>
      <inertia ixx="0.000082" ixy="0.000000" ixz="-0.000007" iyy="0.000082" iyz="-0.000001" izz="0.000042"/>
    </inertial>
    <visual>
      <origin xyz="0 0 0" rpy="0 0 0"/>
      <geometry>
        <mesh filename="package://../meshes/r_leg_upper_g.stl"/>
      </geometry>
      <material name="#ffffff"/>
    </visual>
    <collision>
      <origin xyz="0 0 0" rpy="0 0 0"/>
      <geometry>
        <mesh filename="package://../meshes/r_leg_upper_g.stl"/>
      </geometry>
    </collision>
  </link>

  <joint name="r_leg_upper_g_to_r_knee_g" type="revolute">
    <origin xyz="0.01 -0.0 -0.12" rpy="0.0 0.0 0.0"/>
    <axis xyz="0 1 0"/>
    <parent link="r_leg_upper_g"/>
    <child link="r_knee_g"/>
    <limit lower="-3.14159" upper="3.14159" effort="0" velocity="0"/>
  </joint>

  <link name="r_knee_g">
    <inertial>
      <origin xyz="0 0 0" rpy="0 0 0"/>
      <mass value="0.000000"/>
      <inertia ixx="0.000000" ixy="0.000000" ixz="0.000000" iyy="0.000000" iyz="0.000000" izz="0.000000"/>
    </inertial>
    <visual>
      <origin xyz="0 0 0" rpy="0 0 0"/>
      <geometry>
        <mesh filename="package://../meshes/r_knee_g.stl"/>
      </geometry>
      <material name="#ffffff"/>
    </visual>
    <collision>
      <origin xyz="0 0 0" rpy="0 0 0"/>
      <geometry>
        <mesh filename="package://../meshes/r_knee_g.stl"/>
      </geometry>
    </collision>
  </link>

  <joint name="r_knee_g_to_r_leg_lower_g" type="revolute">
    <origin xyz="0.0 0.0 -0.062" rpy="0.0 0.0 0.0"/>
    <axis xyz="0 1 0"/>
    <parent link="r_knee_g"/>
    <child link="r_leg_lower_g"/>
    <limit lower="-3.14159" upper="3.14159" effort="0" velocity="0"/>
  </joint>

  <link name="r_leg_lower_g">
    <inertial>
      <origin xyz="0 0 0" rpy="0 0 0"/>
      <mass value="0.061000"/>
      <inertia ixx="0.000043" ixy="0.000000" ixz="-0.000001" iyy="0.000037" iyz="-0.000002" izz="0.000018"/>
    </inertial>
    <visual>
      <origin xyz="0 0 0" rpy="0 0 0"/>
      <geometry>
        <mesh filename="package://../meshes/r_leg_lower_g.stl"/>
      </geometry>
      <material name="#ffffff"/>
    </visual>
    <collision>
      <origin xyz="0 0 0" rpy="0 0 0"/>
      <geometry>
        <mesh filename="package://../meshes/r_leg_lower_g.stl"/>
      </geometry>
    </collision>
  </link>

  <joint name="r_leg_lower_g_to_r_ankle_g" type="revolute">
    <origin xyz="-0.01 -0.0 -0.12" rpy="0.0 0.0 0.0"/>
    <axis xyz="1 0 0"/>
    <parent link="r_leg_lower_g"/>
    <child link="r_ankle_g"/>
    <limit lower="-3.14159" upper="3.14159" effort="0" velocity="0"/>
  </joint>

  <link name="r_ankle_g">
    <inertial>
      <origin xyz="0 0 0" rpy="0 0 0"/>
      <mass value="0.058000"/>
      <inertia ixx="0.000058" ixy="0.000001" ixz="-0.000001" iyy="0.000038" iyz="-0.000000" izz="0.000045"/>
    </inertial>
    <visual>
      <origin xyz="0 0 0" rpy="0 0 0"/>
      <geometry>
        <mesh filename="package://../meshes/r_ankle_g.stl"/>
      </geometry>
      <material name="#ffffff"/>
    </visual>
    <collision>
      <origin xyz="0 0 0" rpy="0 0 0"/>
      <geometry>
        <mesh filename="package://../meshes/r_ankle_g.stl"/>
      </geometry>
    </collision>
  </link>

  <joint name="r_ankle_g_to_r_foot_g" type="revolute">
    <origin xyz="0.0 0.0 -0.031" rpy="0.0 0.0 0.0"/>
    <axis xyz="1 0 0"/>
    <parent link="r_ankle_g"/>
    <child link="r_foot_g"/>
    <limit lower="-3.14159" upper="3.14159" effort="0" velocity="0"/>
  </joint>

  <link name="r_foot_g">
    <inertial>
      <origin xyz="0 0 0" rpy="0 0 0"/>
      <mass value="0.045000"/>
      <inertia ixx="0.000061" ixy="-0.000006" ixz="-0.000001" iyy="0.000090" iyz="-0.000003" izz="0.000141"/>
    </inertial>
    <visual>
      <origin xyz="0 0 0" rpy="0 0 0"/>
      <geometry>
        <mesh filename="package://../meshes/r_foot_g.stl"/>
      </geometry>
      <material name="#ffffff"/>
    </visual>
    <collision>
      <origin xyz="0 0 0" rpy="0 0 0"/>
      <geometry>
        <mesh filename="package://../meshes/r_foot_g.stl"/>
      </geometry>
    </collision>
  </link>

  <joint name="r_foot_g_to_r_toe_g" type="revolute">
    <origin xyz="0.07 -0.02 -0.03" rpy="0.0 0.0 0.0"/>
    <axis xyz="1 0 0"/>
    <parent link="r_foot_g"/>
    <child link="r_toe_g"/>
    <limit lower="-3.14159" upper="3.14159" effort="0" velocity="0"/>
  </joint>

  <link name="r_toe_g">
    <inertial>
      <origin xyz="0 0 0" rpy="0 0 0"/>
      <mass value="0.000000"/>
      <inertia ixx="0.000000" ixy="0.000000" ixz="0.000000" iyy="0.000000" iyz="0.000000" izz="0.000000"/>
    </inertial>
    <visual>
      <origin xyz="0 0 0" rpy="0 0 0"/>
      <geometry>
        <mesh filename="package://../meshes/r_toe_g.stl"/>
      </geometry>
      <material name="#ff0000"/>
    </visual>
    <collision>
      <origin xyz="0 0 0" rpy="0 0 0"/>
      <geometry>
        <mesh filename="package://../meshes/r_toe_g.stl"/>
      </geometry>
    </collision>
  </link>

  <joint name="r_leg_lower_g_to_r_leg_lower_g_c" type="revolute">
    <origin xyz="0.0 -0.0 0.0" rpy="0.0 0.0 0.0"/>
    <axis xyz="1 0 0"/>
    <parent link="r_leg_lower_g"/>
    <child link="r_leg_lower_g_c"/>
    <limit lower="-3.14159" upper="3.14159" effort="0" velocity="0"/>
  </joint>

  <link name="r_leg_lower_g_c">
    <inertial>
      <origin xyz="0 0 0" rpy="0 0 0"/>
      <mass value="0.000014"/>
      <inertia ixx="0.000000" ixy="0.000000" ixz="0.000000" iyy="0.000000" iyz="-0.000000" izz="0.000000"/>
    </inertial>
    <visual>
      <origin xyz="0 0 0" rpy="0 0 0"/>
      <geometry>
        <mesh filename="package://../meshes/r_leg_lower_g_c.stl"/>
      </geometry>
      <material name="#ffffff"/>
    </visual>
    <collision>
      <origin xyz="0 0 0" rpy="0 0 0"/>
      <geometry>
        <mesh filename="package://../meshes/r_leg_lower_g_c.stl"/>
      </geometry>
    </collision>
  </link>

  <joint name="r_leg_upper_g_to_r_leg_upper_g_c" type="revolute">
    <origin xyz="0.0 -0.0 -0.12" rpy="0.0 0.0 0.0"/>
    <axis xyz="0 1 0"/>
    <parent link="r_leg_upper_g"/>
    <child link="r_leg_upper_g_c"/>
    <limit lower="-3.14159" upper="3.14159" effort="0" velocity="0"/>
  </joint>

  <link name="r_leg_upper_g_c">
    <inertial>
      <origin xyz="0 0 0" rpy="0 0 0"/>
      <mass value="0.000009"/>
      <inertia ixx="0.000000" ixy="0.000000" ixz="-0.000000" iyy="0.000000" iyz="-0.000000" izz="0.000000"/>
    </inertial>
    <visual>
      <origin xyz="0 0 0" rpy="0 0 0"/>
      <geometry>
        <mesh filename="package://../meshes/r_leg_upper_g_c.stl"/>
      </geometry>
      <material name="#ffffff"/>
    </visual>
    <collision>
      <origin xyz="0 0 0" rpy="0 0 0"/>
      <geometry>
        <mesh filename="package://../meshes/r_leg_upper_g_c.stl"/>
      </geometry>
    </collision>
  </link>

  <joint name="c_waist_g_to_c_waist_g_a" type="revolute">
    <origin xyz="0.033081 -0.0 0.016" rpy="0.0 0.0 0.0"/>
    <axis xyz="1 0 0"/>
    <parent link="c_waist_g"/>
    <child link="c_waist_g_a"/>
    <limit lower="-3.14159" upper="3.14159" effort="0" velocity="0"/>
  </joint>

  <link name="c_waist_g_a">
    <inertial>
      <origin xyz="0 0 0" rpy="0 0 0"/>
      <mass value="0.000000"/>
      <inertia ixx="0.000000" ixy="0.000000" ixz="0.000000" iyy="0.000000" iyz="0.000000" izz="0.000000"/>
    </inertial>
    <visual>
      <origin xyz="0 0 0" rpy="0 0 0"/>
      <geometry>
        <mesh filename="package://../meshes/c_waist_g_a.stl"/>
      </geometry>
      <material name="#ffffff"/>
    </visual>
    <collision>
      <origin xyz="0 0 0" rpy="0 0 0"/>
      <geometry>
        <mesh filename="package://../meshes/c_waist_g_a.stl"/>
      </geometry>
    </collision>
  </link>

  <joint name="c_waist_g_to_c_waist_g_b" type="revolute">
    <origin xyz="-0.065 -0.0 0.016" rpy="0.0 0.0 0.0"/>
    <axis xyz="1 0 0"/>
    <parent link="c_waist_g"/>
    <child link="c_waist_g_b"/>
    <limit lower="-3.14159" upper="3.14159" effort="0" velocity="0"/>
  </joint>

  <link name="c_waist_g_b">
    <inertial>
      <origin xyz="0 0 0" rpy="0 0 0"/>
      <mass value="0.000000"/>
      <inertia ixx="0.000000" ixy="0.000000" ixz="0.000000" iyy="0.000000" iyz="0.000000" izz="0.000000"/>
    </inertial>
    <visual>
      <origin xyz="0 0 0" rpy="0 0 0"/>
      <geometry>
        <mesh filename="package://../meshes/c_waist_g_b.stl"/>
      </geometry>
      <material name="#ffffff"/>
    </visual>
    <collision>
      <origin xyz="0 0 0" rpy="0 0 0"/>
      <geometry>
        <mesh filename="package://../meshes/c_waist_g_b.stl"/>
      </geometry>
    </collision>
  </link>

  <joint name="c_waist_g_to_l_waist_g_a" type="revolute">
    <origin xyz="0.025 0.045 0.016" rpy="0.0 0.0 0.0"/>
    <axis xyz="0 1 0"/>
    <parent link="c_waist_g"/>
    <child link="l_waist_g_a"/>
    <limit lower="-3.14159" upper="3.14159" effort="0" velocity="0"/>
  </joint>

  <link name="l_waist_g_a">
    <inertial>
      <origin xyz="0 0 0" rpy="0 0 0"/>
      <mass value="0.000000"/>
      <inertia ixx="0.000000" ixy="0.000000" ixz="0.000000" iyy="0.000000" iyz="0.000000" izz="0.000000"/>
    </inertial>
    <visual>
      <origin xyz="0 0 0" rpy="0 0 0"/>
      <geometry>
        <mesh filename="package://../meshes/l_waist_g_a.stl"/>
      </geometry>
      <material name="#ffffff"/>
    </visual>
    <collision>
      <origin xyz="0 0 0" rpy="0 0 0"/>
      <geometry>
        <mesh filename="package://../meshes/l_waist_g_a.stl"/>
      </geometry>
    </collision>
  </link>

  <joint name="c_waist_g_to_r_waist_g_a" type="revolute">
    <origin xyz="0.025 -0.045 0.016" rpy="0.0 0.0 0.0"/>
    <axis xyz="0 1 0"/>
    <parent link="c_waist_g"/>
    <child link="r_waist_g_a"/>
    <limit lower="-3.14159" upper="3.14159" effort="0" velocity="0"/>
  </joint>

  <link name="r_waist_g_a">
    <inertial>
      <origin xyz="0 0 0" rpy="0 0 0"/>
      <mass value="0.000000"/>
      <inertia ixx="0.000000" ixy="0.000000" ixz="0.000000" iyy="0.000000" iyz="0.000000" izz="0.000000"/>
    </inertial>
    <visual>
      <origin xyz="0 0 0" rpy="0 0 0"/>
      <geometry>
        <mesh filename="package://../meshes/r_waist_g_a.stl"/>
      </geometry>
      <material name="#ffffff"/>
    </visual>
    <collision>
      <origin xyz="0 0 0" rpy="0 0 0"/>
      <geometry>
        <mesh filename="package://../meshes/r_waist_g_a.stl"/>
      </geometry>
    </collision>
  </link>

</robot>
