<mujoco model="roborecipe1_enemy">
  <compiler angle="radian" meshdir="/home/hori/mujoco/urdf"/>

  <option integrator="implicitfast"/>

  <default>
    <default class="enemy_robo">
      <site rgba="1 0 0 1" size="0.01" group="5"/>
      <joint armature="0.01" frictionloss="0.3"/>
      <position kp="500" dampratio="1"/>
      <default class="enemy_visual">
        <geom group="2" type="mesh" contype="0" conaffinity="0" density="0" material="enemy_metal"/>
      </default>
      <default class="enemy_collision">
        <geom group="3" type="mesh"/>
        <default class="enemy_foot">
          <geom type="sphere" size="0.005" priority="1" friction="0.6" condim="3"/>
        </default>
      </default>
    </default>
  </default>

  <asset>
    <material name="enemy_black" rgba="0.2 0.2 0.2 1"/>
    <material name="enemy_metal" rgba="0.7 0.7 0.7 1"/>
    <material name="enemy_white" rgba="0.933 0.933 0.933 1"/>
    <material name="enemy_orange" rgba="1 0.667 0 1"/>
    <material name="enemy_dark_gray" rgba="0.184 0.184 0.184 1"/>
    <material name="enemy_gray" rgba="0.188 0.188 0.188 1"/>

    <mesh name="enemy_c_waist" file="c_waist.stl" />
    <mesh name="enemy_c_chest" file="c_chest.stl" />
    <mesh name="enemy_c_head" file="c_head.stl" />
    <mesh name="enemy_l_shoulder" file="l_shoulder.stl" />
    <mesh name="enemy_l_arm_upper" file="l_arm_upper.stl" />
    <mesh name="enemy_l_elbow" file="l_elbow.stl" />
    <mesh name="enemy_l_arm_lower" file="l_arm_lower.stl" />
    <mesh name="enemy_l_arm_upper_dec" file="l_arm_upper_dec.stl" />
    <mesh name="enemy_l_shoulder_dec1" file="l_shoulder_dec1.stl" />
    <mesh name="enemy_r_shoulder" file="r_shoulder.stl" />
    <mesh name="enemy_r_arm_upper" file="r_arm_upper.stl" />
    <mesh name="enemy_r_elbow" file="r_elbow.stl" />
    <mesh name="enemy_r_arm_lower" file="r_arm_lower.stl" />
    <mesh name="enemy_r_arm_upper_dec" file="r_arm_upper_dec.stl" />
    <mesh name="enemy_r_shoulder_dec1" file="r_shoulder_dec1.stl" />
    <mesh name="enemy_c_chest_dec1" file="c_chest_dec1.stl" />
    <mesh name="enemy_c_chest_dec2" file="c_chest_dec2.stl" />
    <mesh name="enemy_l_hipjoint_upper" file="l_hipjoint_upper.stl" />
    <mesh name="enemy_l_hipjoint_lower" file="l_hipjoint_lower.stl" />
    <mesh name="enemy_l_leg_upper" file="l_leg_upper.stl" />
    <mesh name="enemy_l_leg_lower" file="l_leg_lower.stl" />
    <mesh name="enemy_l_ankle" file="l_ankle.stl" />
    <mesh name="enemy_l_foot_large" file="l_foot_large.stl" />
    <mesh name="enemy_l_leg_lower_dec1" file="l_leg_lower_dec1.stl" />
    <mesh name="enemy_l_leg_upper_dec1" file="l_leg_upper_dec1.stl" />
    <mesh name="enemy_l_hipjoint_upper_dec1" file="l_hipjoint_upper_dec1.stl" />
    <mesh name="enemy_r_hipjoint_upper" file="r_hipjoint_upper.stl" />
    <mesh name="enemy_r_hipjoint_lower" file="r_hipjoint_lower.stl" />
    <mesh name="enemy_r_leg_upper" file="r_leg_upper.stl" />
    <mesh name="enemy_r_leg_lower" file="r_leg_lower.stl" />
    <mesh name="enemy_r_ankle" file="r_ankle.stl" />
    <mesh name="enemy_r_foot_large" file="r_foot_large.stl" />
    <mesh name="enemy_r_leg_lower_dec1" file="r_leg_lower_dec1.stl" />
    <mesh name="enemy_r_leg_upper_dec1" file="r_leg_upper_dec1.stl" />
    <mesh name="enemy_r_hipjoint_upper_dec1" file="r_hipjoint_upper_dec1.stl" />
  </asset>

  <worldbody>
    <light pos="1 0 3.5" dir="0 0 -1" directional="true"/>
    <!-- 敵ロボット: 30cm前方にZ軸周りに180度回転して向かい合わせ配置 -->
    <body name="enemy_pelvis" pos="0.3 0 0.40" euler="0 0 3.14159" childclass="enemy_robo">
      <inertial pos="0 0 0" quat="1 0 0 0" mass="3.813" diaginertia="0.010549 0.0093089 0.0079184"/>
      <freejoint name="enemy_floating_base_joint"/>
      <site name="enemy_imu_in_pelvis" pos="0 0 0" size="0.01"/>
      <geom class="enemy_visual" material="enemy_gray" mesh="enemy_c_waist" />
      <geom class="enemy_collision" mesh="enemy_c_waist" />
      
      <body name="enemy_c_chest" pos="0 0 0.02">
        <inertial pos="0 0 0" quat="-0.118801 0.647765 0.0252411 0.752097" mass="0.507983" diaginertia="0.00517547 0.00387936 0.00379816" />
        <joint name="enemy_c_chest" pos="0 0 0" axis="0 0 1" range="-3.14159 3.14159" />
        <geom class="enemy_visual" material="enemy_dark_gray" mesh="enemy_c_chest" />
        <geom class="enemy_collision" mesh="enemy_c_chest" />
        <geom class="enemy_visual" material="enemy_white" mesh="enemy_c_chest_dec1" />
        <geom class="enemy_visual" material="enemy_dark_gray" mesh="enemy_c_chest_dec2" />
        <site name="enemy_imu_in_torso" pos="0 0 0.05" size="0.01"/>
        
        <body name="enemy_c_head" pos="0.01145 0 0.0624">
          <inertial pos="0 0 0" quat="0.707107 0 0 0.707107" mass="0.013" diaginertia="2.9e-05 2.2e-05 2.2e-05" />
          <joint name="enemy_c_head" pos="0 0 0" axis="0 0 1" range="-3.14159 3.14159" />
          <geom class="enemy_visual" material="enemy_white" mesh="enemy_c_head" />
          <geom class="enemy_collision" mesh="enemy_c_head" />
        </body>
        
        <body name="enemy_l_shoulder" pos="0.01145 0.04885 0.0454">
          <inertial pos="0 0 0" quat="-0.0568167 0.70482 0.0568167 0.70482" mass="0.014" diaginertia="2.6e-05 2.21623e-05 1.58377e-05" />
          <joint name="enemy_l_shoulder_pitch" pos="0 0 0" axis="0 1 0" range="-3.14159 3.14159" />
          <geom class="visual" material="enemy_white" mesh="enemy_l_shoulder" />
          <geom class="collision" mesh="enemy_l_shoulder" />
          <geom class="visual" material="enemy_orange" mesh="enemy_l_shoulder_dec1" />
          
          <body name="enemy_l_arm_upper" pos="0.01976 0.0256 -2e-05">
            <inertial pos="0 0 0" quat="0.690218 0.126786 0.126002 0.701176" mass="0.098003" diaginertia="0.000322015 0.000261397 0.000112588" />
            <joint name="enemy_l_shoulder_roll" pos="0 0 0" axis="1 0 0" range="-3.14159 3.14159" />
            <geom class="visual" material="enemy_gray" mesh="enemy_l_arm_upper" />
            <geom class="collision" mesh="enemy_l_arm_upper" />
            <geom class="visual" material="enemy_white" mesh="enemy_l_arm_upper_dec" />
            
            <body name="enemy_l_elbow" pos="-0.02 0 -0.074">
              <inertial pos="0 0 0" quat="0.000341234 0.67919 -0.075338 0.730085" mass="0.044" diaginertia="6.22588e-05 5.10972e-05 3.3644e-05" />
              <joint name="enemy_l_elbow_yaw" pos="0 0 0" axis="0 0 1" range="-3.14159 3.14159" />
              <geom class="visual" material="enemy_gray" mesh="enemy_l_elbow" />
              <geom class="collision" mesh="enemy_l_elbow" />
              
              <body name="enemy_l_arm_lower" pos="0.0047 -0.019502 -0.0135">
                <inertial pos="0 0 0" quat="0.998283 0.0139569 -0.0205039 0.053062" mass="0.03" diaginertia="0.000105234 9.49445e-05 2.98213e-05" />
                <joint name="enemy_l_elbow_pitch" pos="0 0 0" axis="0 1 0" range="-3.14159 3.14159" />
                <geom class="visual" material="enemy_white" mesh="enemy_l_arm_lower" />
                <geom class="collision" mesh="enemy_l_arm_lower" />
              </body>
            </body>
          </body>
        </body>
        
        <body name="enemy_r_shoulder" pos="0.01145 -0.04885 0.0454">
          <inertial pos="0 0 0" quat="0.458208 0.538559 -0.458208 0.538559" mass="0.014" diaginertia="2.1e-05 1.61623e-05 9.83772e-06" />
          <joint name="enemy_r_shoulder_pitch" pos="0 0 0" axis="0 1 0" range="-3.14159 3.14159" />
          <geom class="visual" material="enemy_white" mesh="enemy_r_shoulder" />
          <geom class="collision" mesh="enemy_r_shoulder" />
          <geom class="visual" material="enemy_orange" mesh="enemy_r_shoulder_dec1" />
          
          <body name="enemy_r_arm_upper" pos="0.01976 -0.0256 -2e-05">
            <inertial pos="0 0 0" quat="0.695588 0.127111 0.127111 0.695588" mass="0.098003" diaginertia="9.8e-05 7.96716e-05 3.43284e-05" />
            <joint name="enemy_r_shoulder_roll" pos="0 0 0" axis="1 0 0" range="-3.14159 3.14159" />
            <geom class="visual" material="enemy_gray" mesh="enemy_r_arm_upper" />
            <geom class="collision" mesh="enemy_r_arm_upper" />
            <geom class="visual" material="enemy_white" mesh="enemy_r_arm_upper_dec" />
            
            <body name="enemy_r_elbow" pos="-0.02 0 -0.074">
              <inertial pos="0 0 0" quat="-0.0458566 0.659116 0.0826879 0.746073" mass="0.044" diaginertia="1.61281e-05 1.31807e-05 7.69128e-06" />
              <joint name="enemy_r_elbow_yaw" pos="0 0 0" axis="0 0 1" range="-3.14159 3.14159" />
              <geom class="visual" material="enemy_gray" mesh="enemy_r_elbow" />
              <geom class="collision" mesh="enemy_r_elbow" />
              
              <body name="enemy_r_arm_lower" pos="0.0047 0.019502 -0.0135">
                <inertial pos="0 0 0" quat="0.999517 0 -0.0310837 0" mass="0.03" diaginertia="2.30623e-05 2.1e-05 6.93774e-06" />
                <joint name="enemy_r_elbow_pitch" pos="0 0 0" axis="0 1 0" range="-3.14159 3.14159" />
                <geom class="visual" material="enemy_white" mesh="enemy_r_arm_lower" />
                <geom class="collision" mesh="enemy_r_arm_lower" />
              </body>
            </body>
          </body>
        </body>
      </body>
      
      <body name="enemy_l_hipjoint_upper" pos="0 0.02157 -0.02175">
        <inertial pos="0 0 0" quat="0.617602 0.344336 0.617602 0.344336" mass="0.0115" diaginertia="2.32361e-05 1.87639e-05 1.4e-05" />
        <joint name="enemy_l_hip_yaw" pos="0 0 0" axis="0 0 1" range="-3.14159 3.14159" />
        <geom class="visual" material="enemy_white" mesh="enemy_l_hipjoint_upper" />
        <geom class="collision" mesh="enemy_l_hipjoint_upper" />
        <geom class="visual" material="enemy_orange" mesh="enemy_l_hipjoint_upper_dec1" />
        
        <body name="enemy_l_hipjoint_lower" pos="0.02391 -0.00457 -0.02325">
          <inertial pos="0 0 0" quat="0.687649 0.725076 -0.0362929 -0.00935206" mass="0.058" diaginertia="0.000131233 0.000102012 8.47546e-05" />
          <joint name="enemy_l_hip_roll" pos="0 0 0" axis="1 0 0" range="-3.14159 3.14159" />
          <geom class="visual" material="enemy_gray" mesh="enemy_l_hipjoint_lower" />
          <geom class="collision" mesh="enemy_l_hipjoint_lower" />
          
          <body name="enemy_l_leg_upper" pos="-0.01977 -0.00825 -0.0385">
            <inertial pos="0 0 0" quat="0.716578 0.0546044 0.056685 0.693053" mass="0.091009" diaginertia="0.0199742 0.0171032 0.00722157" />
            <joint name="enemy_l_thigh_pitch" pos="0 0 0" axis="0 1 0" range="-3.14159 3.14159" />
            <geom class="visual" material="enemy_gray" mesh="enemy_l_leg_upper" />
            <geom class="collision" mesh="enemy_l_leg_upper" />
            <geom class="visual" material="enemy_white" mesh="enemy_l_leg_upper_dec1" />
            
            <body name="enemy_l_leg_lower" pos="6e-05 2.5e-05 -0.06502">
              <inertial pos="0 0 0" quat="0.998982 0.0416853 0.0163762 -0.0054041" mass="0.061014" diaginertia="0.0001601 0.0001395 6.74e-05" />
              <joint name="enemy_l_knee_pitch" pos="0 0 0" axis="0 1 0" range="-3.14159 3.14159" />
              <geom class="visual" material="enemy_gray" mesh="enemy_l_leg_lower" />
              <geom class="collision" mesh="enemy_l_leg_lower" />
              <geom class="visual" material="enemy_white" mesh="enemy_l_leg_lower_dec1" />
              
              <body name="enemy_l_ankle" pos="1e-05 2.7e-05 -0.0652">
                <inertial pos="0 0 0" quat="0.726153 0.686475 -0.00977331 -0.0368446" mass="0.058" diaginertia="0.000132238 0.000103015 8.67474e-05" />
                <joint name="enemy_l_ankle_pitch" pos="0 0 0" axis="0 1 0" range="-3.14159 3.14159" />
                <geom class="visual" material="enemy_dark_gray" mesh="enemy_l_ankle" />
                <geom class="collision" mesh="enemy_l_ankle" />
                
                <body name="enemy_l_foot_large" pos="0.0198 0.00825 -0.03845">
                  <inertial pos="0 0 0" quat="0.0149445 0.700092 0.0357518 0.713" mass="0.045" diaginertia="0.0302562 0.0228701 0.00989269" />
                  <joint name="enemy_l_ankle_roll" pos="0 0 0" axis="1 0 0" range="-3.14159 3.14159" />
                  <geom class="visual" material="enemy_gray" mesh="enemy_l_foot_large" />
                  <geom class="collision" mesh="enemy_l_foot_large" />
                  <geom class="foot" pos="-0.05 0.025 -0.03"/>
                  <geom class="foot" pos="-0.05 -0.025 -0.03"/>
                  <geom class="foot" pos="0.12 0.03 -0.03"/>
                  <geom class="foot" pos="0.12 -0.03 -0.03"/>
                  <site name="enemy_left_foot"/>
                </body>
              </body>
            </body>
          </body>
        </body>
      </body>
      
      <body name="enemy_r_hipjoint_upper" pos="0 -0.02157 -0.02175">
        <inertial pos="0 0 0" quat="0.438819 0.554471 0.438819 0.554471" mass="0.0115" diaginertia="1.92361e-05 1.47639e-05 1.3e-05" />
        <joint name="enemy_r_hip_yaw" pos="0 0 0" axis="0 0 1" range="-3.14159 3.14159" />
        <geom class="visual" material="enemy_white" mesh="enemy_r_hipjoint_upper" />
        <geom class="collision" mesh="enemy_r_hipjoint_upper" />
        <geom class="visual" material="enemy_orange" mesh="enemy_r_hipjoint_upper_dec1" />
        
        <body name="enemy_r_hipjoint_lower" pos="0.02391 0.00457 -0.02325">
          <inertial pos="0 0 0" quat="0.729426 0.68313 0.00218407 0.0355964" mass="0.058" diaginertia="0.000104156 8.10152e-05 6.68291e-05" />
          <joint name="enemy_r_hip_roll" pos="0 0 0" axis="1 0 0" range="-3.14159 3.14159" />
          <geom class="visual" material="enemy_gray" mesh="enemy_r_hipjoint_lower" />
          <geom class="collision" mesh="enemy_r_hipjoint_lower" />
          
          <body name="enemy_r_leg_upper" pos="-0.01977 0.00825 -0.0385">
            <inertial pos="0 0 0" quat="0.993886 -0.00601543 0.0846436 0.0706334" mass="0.091009" diaginertia="8.32132e-05 8.2e-05 4.07868e-05" />
            <joint name="enemy_r_thigh_pitch" pos="0 0 0" axis="0 1 0" range="-3.14159 3.14159" />
            <geom class="visual" material="enemy_gray" mesh="enemy_r_leg_upper" />
            <geom class="collision" mesh="enemy_r_leg_upper" />
            <geom class="visual" material="enemy_white" mesh="enemy_r_leg_upper_dec1" />
            
            <body name="enemy_r_leg_lower" pos="6e-05 -2.5e-05 -0.06502">
              <inertial pos="0 0 0" quat="0.998437 -0.0515597 0.020118 0.00783329" mass="0.061014" diaginertia="4.3041e-05 3.72064e-05 1.77526e-05" />
              <joint name="enemy_r_knee_pitch" pos="0 0 0" axis="0 1 0" range="-3.14159 3.14159" />
              <geom class="visual" material="enemy_gray" mesh="enemy_r_leg_lower" />
              <geom class="collision" mesh="enemy_r_leg_lower" />
              <geom class="visual" material="enemy_white" mesh="enemy_r_leg_lower_dec1" />
              
              <body name="enemy_r_ankle" pos="1e-05 -2.7e-05 -0.0652">
                <inertial pos="0 0 0" quat="0.709559 0.703186 0.0444071 -0.00913935" mass="0.058" diaginertia="5.81259e-05 4.49244e-05 3.79498e-05" />
                <joint name="enemy_r_ankle_pitch" pos="0 0 0" axis="0 1 0" range="-3.14159 3.14159" />
                <geom class="visual" material="enemy_dark_gray" mesh="enemy_r_ankle" />
                <geom class="collision" mesh="enemy_r_ankle" />
                
                <body name="enemy_r_foot_large" pos="0.0198 -0.00825 -0.03845">
                  <inertial pos="0 0 0" quat="-0.0899717 0.698451 0.0500229 0.708216" mass="0.045" diaginertia="0.000141181 9.10415e-05 5.97774e-05" />
                  <joint name="enemy_r_ankle_roll" pos="0 0 0" axis="1 0 0" range="-3.14159 3.14159" />
                  <geom class="visual" material="enemy_gray" mesh="enemy_r_foot_large" />
                  <geom class="collision" mesh="enemy_r_foot_large" />
                  <geom class="foot" pos="-0.05 0.025 -0.03"/>
                  <geom class="foot" pos="-0.05 -0.025 -0.03"/>
                  <geom class="foot" pos="0.12 0.03 -0.03"/>
                  <geom class="foot" pos="0.12 -0.03 -0.03"/>
                  <site name="enemy_right_foot"/>
                </body>
              </body>
            </body>
          </body>
        </body>
      </body>
    </body>
  </worldbody>

  <actuator>
    <position class="enemy_robo" name="enemy_c_chest" joint="enemy_c_chest"/>
    <position class="enemy_robo" name="enemy_c_head" joint="enemy_c_head"/>
    <position class="enemy_robo" name="enemy_l_shoulder_pitch" joint="enemy_l_shoulder_pitch"/>
    <position class="enemy_robo" name="enemy_l_shoulder_roll" joint="enemy_l_shoulder_roll"/>
    <position class="enemy_robo" name="enemy_l_elbow_yaw" joint="enemy_l_elbow_yaw"/>
    <position class="enemy_robo" name="enemy_l_elbow_pitch" joint="enemy_l_elbow_pitch"/>
    <position class="enemy_robo" name="enemy_r_shoulder_pitch" joint="enemy_r_shoulder_pitch"/>
    <position class="enemy_robo" name="enemy_r_shoulder_roll" joint="enemy_r_shoulder_roll"/>
    <position class="enemy_robo" name="enemy_r_elbow_yaw" joint="enemy_r_elbow_yaw"/>
    <position class="enemy_robo" name="enemy_r_elbow_pitch" joint="enemy_r_elbow_pitch"/>
    <position class="enemy_robo" name="enemy_l_hip_yaw" joint="enemy_l_hip_yaw"/>
    <position class="enemy_robo" name="enemy_l_hip_roll" joint="enemy_l_hip_roll"/>
    <position class="enemy_robo" name="enemy_l_thigh_pitch" joint="enemy_l_thigh_pitch"/>
    <position class="enemy_robo" name="enemy_l_knee_pitch" joint="enemy_l_knee_pitch"/>
    <position class="enemy_robo" name="enemy_l_ankle_pitch" joint="enemy_l_ankle_pitch"/>
    <position class="enemy_robo" name="enemy_l_ankle_roll" joint="enemy_l_ankle_roll"/>
    <position class="enemy_robo" name="enemy_r_hip_yaw" joint="enemy_r_hip_yaw"/>
    <position class="enemy_robo" name="enemy_r_hip_roll" joint="enemy_r_hip_roll"/>
    <position class="enemy_robo" name="enemy_r_thigh_pitch" joint="enemy_r_thigh_pitch"/>
    <position class="enemy_robo" name="enemy_r_knee_pitch" joint="enemy_r_knee_pitch"/>
    <position class="enemy_robo" name="enemy_r_ankle_pitch" joint="enemy_r_ankle_pitch"/>
    <position class="enemy_robo" name="enemy_r_ankle_roll" joint="enemy_r_ankle_roll"/>
  </actuator>

  <sensor>
    <gyro site="enemy_imu_in_torso" name="enemy_imu-torso-angular-velocity" cutoff="34.9" noise="0.0005"/>
    <accelerometer site="enemy_imu_in_torso" name="enemy_imu-torso-linear-acceleration" cutoff="157" noise="0.01"/>
    <gyro site="enemy_imu_in_pelvis" name="enemy_imu-pelvis-angular-velocity" cutoff="34.9" noise="0.0005"/>
    <accelerometer site="enemy_imu_in_pelvis" name="enemy_imu-pelvis-linear-acceleration" cutoff="157" noise="0.01"/>
  </sensor>
</mujoco>